<?xml version="1.0"?>
<robot name="ak80_8" xmlns:xacro="http://www.ros.org/wiki/xacro">
  <!-- Include ros2 control tags -->
  <xacro:include filename="$(find levion_arm_ros2_control)/ros2_control/ak80_8.ros2_control.xacro"/>

  <!-- Main URDF -->
  <link name="ak80_8_bottom">
    <visual>
      <origin xyz="0 0 0" rpy="0 0 0"/>
      <geometry>
        <!-- <mesh filename="$(find levion_arm_ros2_control)/description/mesh/3D-AK80-8.stp" scale="1 1 1"/> -->
        <cylinder radius=".08" length="0.05"/>
      </geometry>
    </visual>
    <collision>
      <origin xyz="0 0 0" rpy="0 0 0"/>
      <geometry>
        <cylinder radius=".08" length="0.05"/>
      </geometry>
    </collision>
    <inertial>
      <origin xyz="0 0 0" rpy="0 0 0"/>
      <mass value="0.1"/>
      <inertia ixx="0.0001" ixy="0.0" ixz="0.0" iyy="0.0001" iyz="0.0" izz="0.0001"/>
    </inertial>
  </link>

  <link name="ak80_8_top">
    <visual>
      <origin xyz="0 0 0" rpy="0 0 0"/>
      <geometry>
        <!-- <mesh filename="$(find levion_arm_ros2_control)/description/mesh/3D-AK80-8.stp" scale="1 1 1"/> -->
        <cylinder radius=".04" length="0.01"/>
      </geometry>
    </visual>
    <collision>
      <origin xyz="0 0 0" rpy="0 0 0"/>
      <geometry>
        <cylinder radius=".04" length="0.01"/>
      </geometry>
    </collision>
    <inertial>
      <origin xyz="0 0 0" rpy="0 0 0"/>
      <mass value="0.1"/>
      <inertia ixx="0.0001" ixy="0.0" ixz="0.0" iyy="0.0001" iyz="0.0" izz="0.0001"/>
    </inertial>
  </link>
  

  <joint name="ak80_8_joint" type="revolute">
    <origin xyz="0 0 0.03" rpy="0 0 0"/>
    <parent link="ak80_8_bottom"/>
    <child link="ak80_8_top"/>
    <axis xyz="0 0 1"/>
    <limit lower="-3.14159265359" upper="3.14159265359" effort="10" velocity="10"/>
  </joint>

</robot>
